<?xml version="1.0" encoding="UTF-8"?>
<testng-results skipped="1" failed="1" total="3" passed="1">
  <reporter-output>
  </reporter-output>
  <suite name="Suite" duration-ms="376" started-at="2017-03-29T09:19:04Z" finished-at="2017-03-29T09:19:04Z">
    <groups>
    </groups>
    <test name="Test" duration-ms="376" started-at="2017-03-29T09:19:04Z" finished-at="2017-03-29T09:19:04Z">
      <class name="com.testng.demo.SampleTest">
        <test-method status="FAIL" signature="testMethodTwo()[pri:0, instance:com.testng.demo.SampleTest@2d6e8792]" name="testMethodTwo" duration-ms="60" started-at="2017-03-29T17:19:04Z" finished-at="2017-03-29T17:19:04Z">
          <exception class="java.lang.AssertionError">
            <message>
              <![CDATA[expected [true] but found [false]]]>
            </message>
            <full-stacktrace>
              <![CDATA[java.lang.AssertionError: expected [true] but found [false]
	at org.testng.Assert.fail(Assert.java:94)
	at org.testng.Assert.failNotEquals(Assert.java:494)
	at org.testng.Assert.assertTrue(Assert.java:42)
	at org.testng.Assert.assertTrue(Assert.java:52)
	at com.testng.demo.SampleTest.testMethodTwo(SampleTest.java:14)
	at sun.reflect.NativeMethodAccessorImpl.invoke0(Native Method)
	at sun.reflect.NativeMethodAccessorImpl.invoke(Unknown Source)
	at sun.reflect.DelegatingMethodAccessorImpl.invoke(Unknown Source)
	at java.lang.reflect.Method.invoke(Unknown Source)
	at org.testng.internal.MethodInvocationHelper.invokeMethod(MethodInvocationHelper.java:84)
	at org.testng.internal.Invoker.invokeMethod(Invoker.java:714)
	at org.testng.internal.Invoker.invokeTestMethod(Invoker.java:901)
	at org.testng.internal.Invoker.invokeTestMethods(Invoker.java:1231)
	at org.testng.internal.TestMethodWorker.invokeTestMethods(TestMethodWorker.java:127)
	at org.testng.internal.TestMethodWorker.run(TestMethodWorker.java:111)
	at org.testng.TestRunner.privateRun(TestRunner.java:767)
	at org.testng.TestRunner.run(TestRunner.java:617)
	at org.testng.SuiteRunner.runTest(SuiteRunner.java:334)
	at org.testng.SuiteRunner.runSequentially(SuiteRunner.java:329)
	at org.testng.SuiteRunner.privateRun(SuiteRunner.java:291)
	at org.testng.SuiteRunner.run(SuiteRunner.java:240)
	at org.testng.SuiteRunnerWorker.runSuite(SuiteRunnerWorker.java:52)
	at org.testng.SuiteRunnerWorker.run(SuiteRunnerWorker.java:86)
	at org.testng.TestNG.runSuitesSequentially(TestNG.java:1224)
	at org.testng.TestNG.runSuitesLocally(TestNG.java:1149)
	at org.testng.TestNG.run(TestNG.java:1057)
	at org.testng.remote.RemoteTestNG.run(RemoteTestNG.java:111)
	at org.testng.remote.RemoteTestNG.initAndRun(RemoteTestNG.java:204)
	at org.testng.remote.RemoteTestNG.main(RemoteTestNG.java:175)
]]>
            </full-stacktrace>
          </exception> <!-- java.lang.AssertionError -->
          <reporter-output>
          </reporter-output>
        </test-method> <!-- testMethodTwo -->
        <test-method status="PASS" signature="testMethodOne()[pri:0, instance:com.testng.demo.SampleTest@2d6e8792]" name="testMethodOne" duration-ms="8" started-at="2017-03-29T17:19:04Z" finished-at="2017-03-29T17:19:04Z">
          <reporter-output>
          </reporter-output>
        </test-method> <!-- testMethodOne -->
        <test-method status="SKIP" signature="testMethodThree()[pri:0, instance:com.testng.demo.SampleTest@2d6e8792]" name="testMethodThree" duration-ms="154" started-at="2017-03-29T17:19:04Z" depends-on-methods="com.testng.demo.SampleTest.testMethodTwo" finished-at="2017-03-29T17:19:04Z">
          <reporter-output>
          </reporter-output>
        </test-method> <!-- testMethodThree -->
      </class> <!-- com.testng.demo.SampleTest -->
    </test> <!-- Test -->
  </suite> <!-- Suite -->
</testng-results>
